Traceback (most recent call last):
  File "/Users/tsauter/venv/lib/python3.7/site-packages/jupyter_cache/executors/utils.py", line 56, in single_nb_execution
    record_timing=False,
  File "/Users/tsauter/venv/lib/python3.7/site-packages/nbclient/client.py", line 1117, in execute
    return NotebookClient(nb=nb, resources=resources, km=km, **kwargs).execute()
  File "/Users/tsauter/venv/lib/python3.7/site-packages/nbclient/util.py", line 78, in wrapped
    return just_run(coro(*args, **kwargs))
  File "/Users/tsauter/venv/lib/python3.7/site-packages/nbclient/util.py", line 57, in just_run
    return loop.run_until_complete(coro)
  File "/Library/Frameworks/Python.framework/Versions/3.7/lib/python3.7/asyncio/base_events.py", line 568, in run_until_complete
    return future.result()
  File "/Users/tsauter/venv/lib/python3.7/site-packages/nbclient/client.py", line 559, in async_execute
    cell, index, execution_count=self.code_cells_executed + 1
  File "/Users/tsauter/venv/lib/python3.7/site-packages/nbclient/client.py", line 862, in async_execute_cell
    self._check_raise_for_error(cell, exec_reply)
  File "/Users/tsauter/venv/lib/python3.7/site-packages/nbclient/client.py", line 765, in _check_raise_for_error
    raise CellExecutionError.from_cell_and_msg(cell, exec_reply_content)
nbclient.exceptions.CellExecutionError: An error occurred while executing the following cell:
------------------
import numpy as np
import matplotlib.pyplot as plt

Km = 0.1
Kh = 0.01
g = 9.81
lapse = 0.004
s = -5
s = np.sin(s*3.14/180)
C = -5
T0 = 280
zmax = 100


lam = ((4*T0*Km*Kh)/(g*s**2*lapse))**(0.25)
mu = ((g*Kh)/(T0*Km*lapse))**(0.5)

theta1 = [C*np.exp(-z/lam)*np.cos(-z/lam) for z in np.arange(0,zmax,0.5)]
u1 = [C*mu*np.exp(-z/lam)*np.sin(-z/lam) for z in np.arange(0,zmax,0.5)]

lam2 = ((g*s**2*lapse)/(4*T0*Km*Kh))**(0.25)

theta3 = [C*np.exp(-z*lam2)*np.cos(-z*lam2) for z in np.arange(0,zmax,0.5)]
#theta2 = [C*np.exp(-z*lam2)*np.cos(-z*lam2) for z in np.arange(0,zmax,0.5)]
#u2 = [C*np.exp(-z*lam2)*np.sin(-z*lam2) for z in np.arange(0,zmax,0.5)]

print(np.max(np.array(u1)-np.array(u2)))
print(np.max(np.array(theta1)-np.array(theta2)))
print(1/lam,lam2)

plt.plot(theta1,np.arange(0,zmax,0.5))
plt.plot(u1,np.arange(0,zmax,0.5))

plt.plot(theta2,np.arange(0,zmax,0.5))
plt.plot(u2,np.arange(0,zmax,0.5))
------------------

[0;31m---------------------------------------------------------------------------[0m
[0;31mNameError[0m                                 Traceback (most recent call last)
[0;32m/var/folders/tt/q4k5594x1tz82j1yrmtkdw080000gn/T/ipykernel_4459/2502441394.py[0m in [0;36m<module>[0;34m[0m
[1;32m     25[0m [0;31m#u2 = [C*np.exp(-z*lam2)*np.sin(-z*lam2) for z in np.arange(0,zmax,0.5)][0m[0;34m[0m[0;34m[0m[0m
[1;32m     26[0m [0;34m[0m[0m
[0;32m---> 27[0;31m [0mprint[0m[0;34m([0m[0mnp[0m[0;34m.[0m[0mmax[0m[0;34m([0m[0mnp[0m[0;34m.[0m[0marray[0m[0;34m([0m[0mu1[0m[0;34m)[0m[0;34m-[0m[0mnp[0m[0;34m.[0m[0marray[0m[0;34m([0m[0mu2[0m[0;34m)[0m[0;34m)[0m[0;34m)[0m[0;34m[0m[0m
[0m[1;32m     28[0m [0mprint[0m[0;34m([0m[0mnp[0m[0;34m.[0m[0mmax[0m[0;34m([0m[0mnp[0m[0;34m.[0m[0marray[0m[0;34m([0m[0mtheta1[0m[0;34m)[0m[0;34m-[0m[0mnp[0m[0;34m.[0m[0marray[0m[0;34m([0m[0mtheta2[0m[0;34m)[0m[0;34m)[0m[0;34m)[0m[0;34m[0m[0m
[1;32m     29[0m [0mprint[0m[0;34m([0m[0;36m1[0m[0;34m/[0m[0mlam[0m[0;34m,[0m[0mlam2[0m[0;34m)[0m[0;34m[0m[0m

[0;31mNameError[0m: name 'u2' is not defined
NameError: name 'u2' is not defined

